[2024-04-29T16:46:44.638+0000] {local_task_job_runner.py:120} INFO - ::group::Pre task execution logs
[2024-04-29T16:46:44.756+0000] {taskinstance.py:2073} INFO - Dependencies all met for dep_context=non-requeueable deps ti=<TaskInstance: fill_data_v6.raw scheduled__2024-04-28T00:00:00+00:00 [queued]>
[2024-04-29T16:46:44.763+0000] {taskinstance.py:2073} INFO - Dependencies all met for dep_context=requeueable deps ti=<TaskInstance: fill_data_v6.raw scheduled__2024-04-28T00:00:00+00:00 [queued]>
[2024-04-29T16:46:44.766+0000] {taskinstance.py:2303} INFO - Starting attempt 2 of 6
[2024-04-29T16:46:44.776+0000] {taskinstance.py:2327} INFO - Executing <Task(PythonOperator): raw> on 2024-04-28 00:00:00+00:00
[2024-04-29T16:46:44.781+0000] {standard_task_runner.py:90} INFO - Running: ['***', 'tasks', 'run', 'fill_data_v6', 'raw', 'scheduled__2024-04-28T00:00:00+00:00', '--job-id', '6', '--raw', '--subdir', 'DAGS_FOLDER/dag_raw_processed.py', '--cfg-path', '/tmp/tmpvub83jbs']
[2024-04-29T16:46:44.783+0000] {logging_mixin.py:188} WARNING - /home/***/.local/lib/python3.12/site-packages/***/task/task_runner/standard_task_runner.py:61 DeprecationWarning: This process (pid=379) is multi-threaded, use of fork() may lead to deadlocks in the child.
[2024-04-29T16:46:44.783+0000] {standard_task_runner.py:91} INFO - Job 6: Subtask raw
[2024-04-29T16:46:44.784+0000] {standard_task_runner.py:63} INFO - Started process 381 to run task
[2024-04-29T16:46:44.820+0000] {task_command.py:426} INFO - Running <TaskInstance: fill_data_v6.raw scheduled__2024-04-28T00:00:00+00:00 [running]> on host 15fcc90b2790
[2024-04-29T16:46:44.878+0000] {taskinstance.py:2644} INFO - Exporting env vars: AIRFLOW_CTX_DAG_OWNER='mosula' AIRFLOW_CTX_DAG_ID='fill_data_v6' AIRFLOW_CTX_TASK_ID='raw' AIRFLOW_CTX_EXECUTION_DATE='2024-04-28T00:00:00+00:00' AIRFLOW_CTX_TRY_NUMBER='2' AIRFLOW_CTX_DAG_RUN_ID='scheduled__2024-04-28T00:00:00+00:00'
[2024-04-29T16:46:44.879+0000] {taskinstance.py:430} INFO - ::endgroup::
[2024-04-29T16:46:44.889+0000] {logging_mixin.py:188} INFO - ['dags', 'logs', '***.cfg', 'data']
[2024-04-29T16:46:44.929+0000] {taskinstance.py:441} INFO - ::group::Post task execution logs
[2024-04-29T16:46:44.930+0000] {taskinstance.py:2890} ERROR - Task failed with exception
Traceback (most recent call last):
  File "/home/airflow/.local/lib/python3.12/site-packages/airflow/models/taskinstance.py", line 465, in _execute_task
    result = _execute_callable(context=context, **execute_callable_kwargs)
             ^^^^^^^^^^^^^^^^^^^^^^^^^^^^^^^^^^^^^^^^^^^^^^^^^^^^^^^^^^^^^
  File "/home/airflow/.local/lib/python3.12/site-packages/airflow/models/taskinstance.py", line 432, in _execute_callable
    return execute_callable(context=context, **execute_callable_kwargs)
           ^^^^^^^^^^^^^^^^^^^^^^^^^^^^^^^^^^^^^^^^^^^^^^^^^^^^^^^^^^^^
  File "/home/airflow/.local/lib/python3.12/site-packages/airflow/models/baseoperator.py", line 400, in wrapper
    return func(self, *args, **kwargs)
           ^^^^^^^^^^^^^^^^^^^^^^^^^^^
  File "/home/airflow/.local/lib/python3.12/site-packages/airflow/operators/python.py", line 235, in execute
    return_value = self.execute_callable()
                   ^^^^^^^^^^^^^^^^^^^^^^^
  File "/home/airflow/.local/lib/python3.12/site-packages/airflow/operators/python.py", line 252, in execute_callable
    return self.python_callable(*self.op_args, **self.op_kwargs)
           ^^^^^^^^^^^^^^^^^^^^^^^^^^^^^^^^^^^^^^^^^^^^^^^^^^^^^
  File "/opt/airflow/dags/dag_raw_processed.py", line 25, in fill_raw
    conn = psycopg2.connect(dbname="churn", user="airflow", password="airflow", host="localhost")
           ^^^^^^^^^^^^^^^^^^^^^^^^^^^^^^^^^^^^^^^^^^^^^^^^^^^^^^^^^^^^^^^^^^^^^^^^^^^^^^^^^^^^^^
  File "/home/airflow/.local/lib/python3.12/site-packages/psycopg2/__init__.py", line 122, in connect
    conn = _connect(dsn, connection_factory=connection_factory, **kwasync)
           ^^^^^^^^^^^^^^^^^^^^^^^^^^^^^^^^^^^^^^^^^^^^^^^^^^^^^^^^^^^^^^^
psycopg2.OperationalError: connection to server at "localhost" (127.0.0.1), port 5432 failed: Connection refused
	Is the server running on that host and accepting TCP/IP connections?
connection to server at "localhost" (::1), port 5432 failed: Cannot assign requested address
	Is the server running on that host and accepting TCP/IP connections?

[2024-04-29T16:46:44.945+0000] {taskinstance.py:1205} INFO - Marking task as UP_FOR_RETRY. dag_id=fill_data_v6, task_id=raw, execution_date=20240428T000000, start_date=20240429T164644, end_date=20240429T164644
[2024-04-29T16:46:44.957+0000] {standard_task_runner.py:110} ERROR - Failed to execute job 6 for task raw (connection to server at "localhost" (127.0.0.1), port 5432 failed: Connection refused
	Is the server running on that host and accepting TCP/IP connections?
connection to server at "localhost" (::1), port 5432 failed: Cannot assign requested address
	Is the server running on that host and accepting TCP/IP connections?
; 381)
[2024-04-29T16:46:44.999+0000] {local_task_job_runner.py:240} INFO - Task exited with return code 1
[2024-04-29T16:46:45.014+0000] {taskinstance.py:3482} INFO - 0 downstream tasks scheduled from follow-on schedule check
[2024-04-29T16:46:45.017+0000] {local_task_job_runner.py:222} INFO - ::endgroup::
