[2024-04-29T16:27:06.555+0000] {local_task_job_runner.py:120} INFO - ::group::Pre task execution logs
[2024-04-29T16:27:06.709+0000] {taskinstance.py:2073} INFO - Dependencies all met for dep_context=non-requeueable deps ti=<TaskInstance: fill_data_v5.raw scheduled__2024-04-28T00:00:00+00:00 [queued]>
[2024-04-29T16:27:06.721+0000] {taskinstance.py:2073} INFO - Dependencies all met for dep_context=requeueable deps ti=<TaskInstance: fill_data_v5.raw scheduled__2024-04-28T00:00:00+00:00 [queued]>
[2024-04-29T16:27:06.724+0000] {taskinstance.py:2303} INFO - Starting attempt 1 of 6
[2024-04-29T16:27:06.739+0000] {taskinstance.py:2327} INFO - Executing <Task(PythonOperator): raw> on 2024-04-28 00:00:00+00:00
[2024-04-29T16:27:06.746+0000] {standard_task_runner.py:90} INFO - Running: ['***', 'tasks', 'run', 'fill_data_v5', 'raw', 'scheduled__2024-04-28T00:00:00+00:00', '--job-id', '10', '--raw', '--subdir', 'DAGS_FOLDER/dag_raw_processed.py', '--cfg-path', '/tmp/tmp9xqfr0ca']
[2024-04-29T16:27:06.749+0000] {standard_task_runner.py:91} INFO - Job 10: Subtask raw
[2024-04-29T16:27:06.749+0000] {logging_mixin.py:188} WARNING - /home/***/.local/lib/python3.12/site-packages/***/task/task_runner/standard_task_runner.py:61 DeprecationWarning: This process (pid=565) is multi-threaded, use of fork() may lead to deadlocks in the child.
[2024-04-29T16:27:06.751+0000] {standard_task_runner.py:63} INFO - Started process 567 to run task
[2024-04-29T16:27:06.812+0000] {task_command.py:426} INFO - Running <TaskInstance: fill_data_v5.raw scheduled__2024-04-28T00:00:00+00:00 [running]> on host 8865bf60ce19
[2024-04-29T16:27:06.924+0000] {taskinstance.py:2644} INFO - Exporting env vars: AIRFLOW_CTX_DAG_OWNER='mosula' AIRFLOW_CTX_DAG_ID='fill_data_v5' AIRFLOW_CTX_TASK_ID='raw' AIRFLOW_CTX_EXECUTION_DATE='2024-04-28T00:00:00+00:00' AIRFLOW_CTX_TRY_NUMBER='1' AIRFLOW_CTX_DAG_RUN_ID='scheduled__2024-04-28T00:00:00+00:00'
[2024-04-29T16:27:06.925+0000] {taskinstance.py:430} INFO - ::endgroup::
[2024-04-29T16:27:06.937+0000] {logging_mixin.py:188} INFO - ['dags', 'logs', '***.cfg', 'data']
[2024-04-29T16:27:06.940+0000] {taskinstance.py:441} INFO - ::group::Post task execution logs
[2024-04-29T16:27:06.941+0000] {taskinstance.py:2890} ERROR - Task failed with exception
Traceback (most recent call last):
  File "/home/airflow/.local/lib/python3.12/site-packages/airflow/models/taskinstance.py", line 465, in _execute_task
    result = _execute_callable(context=context, **execute_callable_kwargs)
             ^^^^^^^^^^^^^^^^^^^^^^^^^^^^^^^^^^^^^^^^^^^^^^^^^^^^^^^^^^^^^
  File "/home/airflow/.local/lib/python3.12/site-packages/airflow/models/taskinstance.py", line 432, in _execute_callable
    return execute_callable(context=context, **execute_callable_kwargs)
           ^^^^^^^^^^^^^^^^^^^^^^^^^^^^^^^^^^^^^^^^^^^^^^^^^^^^^^^^^^^^
  File "/home/airflow/.local/lib/python3.12/site-packages/airflow/models/baseoperator.py", line 400, in wrapper
    return func(self, *args, **kwargs)
           ^^^^^^^^^^^^^^^^^^^^^^^^^^^
  File "/home/airflow/.local/lib/python3.12/site-packages/airflow/operators/python.py", line 235, in execute
    return_value = self.execute_callable()
                   ^^^^^^^^^^^^^^^^^^^^^^^
  File "/home/airflow/.local/lib/python3.12/site-packages/airflow/operators/python.py", line 252, in execute_callable
    return self.python_callable(*self.op_args, **self.op_kwargs)
           ^^^^^^^^^^^^^^^^^^^^^^^^^^^^^^^^^^^^^^^^^^^^^^^^^^^^^
  File "/opt/airflow/dags/dag_raw_processed.py", line 19, in fill_raw
    df = pd.read_csv(os.path.join(os.getcwd(), 'data', data_name))
         ^^^^^^^^^^^^^^^^^^^^^^^^^^^^^^^^^^^^^^^^^^^^^^^^^^^^^^^^^
  File "/home/airflow/.local/lib/python3.12/site-packages/pandas/io/parsers/readers.py", line 1026, in read_csv
    return _read(filepath_or_buffer, kwds)
           ^^^^^^^^^^^^^^^^^^^^^^^^^^^^^^^
  File "/home/airflow/.local/lib/python3.12/site-packages/pandas/io/parsers/readers.py", line 620, in _read
    parser = TextFileReader(filepath_or_buffer, **kwds)
             ^^^^^^^^^^^^^^^^^^^^^^^^^^^^^^^^^^^^^^^^^^
  File "/home/airflow/.local/lib/python3.12/site-packages/pandas/io/parsers/readers.py", line 1620, in __init__
    self._engine = self._make_engine(f, self.engine)
                   ^^^^^^^^^^^^^^^^^^^^^^^^^^^^^^^^^
  File "/home/airflow/.local/lib/python3.12/site-packages/pandas/io/parsers/readers.py", line 1880, in _make_engine
    self.handles = get_handle(
                   ^^^^^^^^^^^
  File "/home/airflow/.local/lib/python3.12/site-packages/pandas/io/common.py", line 873, in get_handle
    handle = open(
             ^^^^^
FileNotFoundError: [Errno 2] No such file or directory: '/opt/airflow/data/data.csv'
[2024-04-29T16:27:06.964+0000] {taskinstance.py:1205} INFO - Marking task as UP_FOR_RETRY. dag_id=fill_data_v5, task_id=raw, execution_date=20240428T000000, start_date=20240429T162706, end_date=20240429T162706
[2024-04-29T16:27:06.981+0000] {standard_task_runner.py:110} ERROR - Failed to execute job 10 for task raw ([Errno 2] No such file or directory: '/opt/airflow/data/data.csv'; 567)
[2024-04-29T16:27:07.007+0000] {local_task_job_runner.py:240} INFO - Task exited with return code 1
[2024-04-29T16:27:07.041+0000] {taskinstance.py:3482} INFO - 0 downstream tasks scheduled from follow-on schedule check
[2024-04-29T16:27:07.048+0000] {local_task_job_runner.py:222} INFO - ::endgroup::
[2024-04-29T16:39:39.492+0000] {local_task_job_runner.py:120} INFO - ::group::Pre task execution logs
[2024-04-29T16:39:39.621+0000] {taskinstance.py:2073} INFO - Dependencies all met for dep_context=non-requeueable deps ti=<TaskInstance: fill_data_v5.raw scheduled__2024-04-28T00:00:00+00:00 [queued]>
[2024-04-29T16:39:39.628+0000] {taskinstance.py:2073} INFO - Dependencies all met for dep_context=requeueable deps ti=<TaskInstance: fill_data_v5.raw scheduled__2024-04-28T00:00:00+00:00 [queued]>
[2024-04-29T16:39:39.629+0000] {taskinstance.py:2303} INFO - Starting attempt 1 of 6
[2024-04-29T16:39:39.641+0000] {taskinstance.py:2327} INFO - Executing <Task(PythonOperator): raw> on 2024-04-28 00:00:00+00:00
[2024-04-29T16:39:39.647+0000] {standard_task_runner.py:90} INFO - Running: ['***', 'tasks', 'run', 'fill_data_v5', 'raw', 'scheduled__2024-04-28T00:00:00+00:00', '--job-id', '4', '--raw', '--subdir', 'DAGS_FOLDER/dag_raw_processed.py', '--cfg-path', '/tmp/tmp0ioqaoxo']
[2024-04-29T16:39:39.648+0000] {logging_mixin.py:188} WARNING - /home/***/.local/lib/python3.12/site-packages/***/task/task_runner/standard_task_runner.py:61 DeprecationWarning: This process (pid=205) is multi-threaded, use of fork() may lead to deadlocks in the child.
[2024-04-29T16:39:39.649+0000] {standard_task_runner.py:91} INFO - Job 4: Subtask raw
[2024-04-29T16:39:39.650+0000] {standard_task_runner.py:63} INFO - Started process 207 to run task
[2024-04-29T16:39:39.688+0000] {task_command.py:426} INFO - Running <TaskInstance: fill_data_v5.raw scheduled__2024-04-28T00:00:00+00:00 [running]> on host 15fcc90b2790
[2024-04-29T16:39:39.749+0000] {taskinstance.py:2644} INFO - Exporting env vars: AIRFLOW_CTX_DAG_OWNER='mosula' AIRFLOW_CTX_DAG_ID='fill_data_v5' AIRFLOW_CTX_TASK_ID='raw' AIRFLOW_CTX_EXECUTION_DATE='2024-04-28T00:00:00+00:00' AIRFLOW_CTX_TRY_NUMBER='1' AIRFLOW_CTX_DAG_RUN_ID='scheduled__2024-04-28T00:00:00+00:00'
[2024-04-29T16:39:39.750+0000] {taskinstance.py:430} INFO - ::endgroup::
[2024-04-29T16:39:39.758+0000] {logging_mixin.py:188} INFO - ['dags', 'logs', '***.cfg', 'data']
[2024-04-29T16:39:39.810+0000] {taskinstance.py:441} INFO - ::group::Post task execution logs
[2024-04-29T16:39:39.812+0000] {taskinstance.py:2890} ERROR - Task failed with exception
Traceback (most recent call last):
  File "/home/airflow/.local/lib/python3.12/site-packages/airflow/models/taskinstance.py", line 465, in _execute_task
    result = _execute_callable(context=context, **execute_callable_kwargs)
             ^^^^^^^^^^^^^^^^^^^^^^^^^^^^^^^^^^^^^^^^^^^^^^^^^^^^^^^^^^^^^
  File "/home/airflow/.local/lib/python3.12/site-packages/airflow/models/taskinstance.py", line 432, in _execute_callable
    return execute_callable(context=context, **execute_callable_kwargs)
           ^^^^^^^^^^^^^^^^^^^^^^^^^^^^^^^^^^^^^^^^^^^^^^^^^^^^^^^^^^^^
  File "/home/airflow/.local/lib/python3.12/site-packages/airflow/models/baseoperator.py", line 400, in wrapper
    return func(self, *args, **kwargs)
           ^^^^^^^^^^^^^^^^^^^^^^^^^^^
  File "/home/airflow/.local/lib/python3.12/site-packages/airflow/operators/python.py", line 235, in execute
    return_value = self.execute_callable()
                   ^^^^^^^^^^^^^^^^^^^^^^^
  File "/home/airflow/.local/lib/python3.12/site-packages/airflow/operators/python.py", line 252, in execute_callable
    return self.python_callable(*self.op_args, **self.op_kwargs)
           ^^^^^^^^^^^^^^^^^^^^^^^^^^^^^^^^^^^^^^^^^^^^^^^^^^^^^
  File "/opt/airflow/dags/dag_raw_processed.py", line 25, in fill_raw
    conn = psycopg2.connect(dbname="churn", user="airflow", password="airflow", host="localhost")
           ^^^^^^^^^^^^^^^^^^^^^^^^^^^^^^^^^^^^^^^^^^^^^^^^^^^^^^^^^^^^^^^^^^^^^^^^^^^^^^^^^^^^^^
  File "/home/airflow/.local/lib/python3.12/site-packages/psycopg2/__init__.py", line 122, in connect
    conn = _connect(dsn, connection_factory=connection_factory, **kwasync)
           ^^^^^^^^^^^^^^^^^^^^^^^^^^^^^^^^^^^^^^^^^^^^^^^^^^^^^^^^^^^^^^^
psycopg2.OperationalError: connection to server at "localhost" (127.0.0.1), port 5432 failed: Connection refused
	Is the server running on that host and accepting TCP/IP connections?
connection to server at "localhost" (::1), port 5432 failed: Cannot assign requested address
	Is the server running on that host and accepting TCP/IP connections?

[2024-04-29T16:39:39.832+0000] {taskinstance.py:1205} INFO - Marking task as UP_FOR_RETRY. dag_id=fill_data_v5, task_id=raw, execution_date=20240428T000000, start_date=20240429T163939, end_date=20240429T163939
[2024-04-29T16:39:39.843+0000] {standard_task_runner.py:110} ERROR - Failed to execute job 4 for task raw (connection to server at "localhost" (127.0.0.1), port 5432 failed: Connection refused
	Is the server running on that host and accepting TCP/IP connections?
connection to server at "localhost" (::1), port 5432 failed: Cannot assign requested address
	Is the server running on that host and accepting TCP/IP connections?
; 207)
[2024-04-29T16:39:39.866+0000] {local_task_job_runner.py:240} INFO - Task exited with return code 1
[2024-04-29T16:39:39.882+0000] {taskinstance.py:3482} INFO - 0 downstream tasks scheduled from follow-on schedule check
[2024-04-29T16:39:39.886+0000] {local_task_job_runner.py:222} INFO - ::endgroup::
