[2024-04-29T20:00:10.586+0000] {local_task_job_runner.py:120} INFO - ::group::Pre task execution logs
[2024-04-29T20:00:10.614+0000] {taskinstance.py:2073} INFO - Dependencies all met for dep_context=non-requeueable deps ti=<TaskInstance: predict_v11.train scheduled__2024-04-28T00:00:00+00:00 [queued]>
[2024-04-29T20:00:10.622+0000] {taskinstance.py:2073} INFO - Dependencies all met for dep_context=requeueable deps ti=<TaskInstance: predict_v11.train scheduled__2024-04-28T00:00:00+00:00 [queued]>
[2024-04-29T20:00:10.625+0000] {taskinstance.py:2303} INFO - Starting attempt 1 of 6
[2024-04-29T20:00:10.638+0000] {taskinstance.py:2327} INFO - Executing <Task(PythonOperator): train> on 2024-04-28 00:00:00+00:00
[2024-04-29T20:00:10.650+0000] {standard_task_runner.py:90} INFO - Running: ['***', 'tasks', 'run', 'predict_v11', 'train', 'scheduled__2024-04-28T00:00:00+00:00', '--job-id', '10', '--raw', '--subdir', 'DAGS_FOLDER/dag_predict.py', '--cfg-path', '/tmp/tmpha4012uj']
[2024-04-29T20:00:10.655+0000] {standard_task_runner.py:91} INFO - Job 10: Subtask train
[2024-04-29T20:00:10.657+0000] {logging_mixin.py:188} WARNING - /home/***/.local/lib/python3.12/site-packages/***/task/task_runner/standard_task_runner.py:61 DeprecationWarning: This process (pid=1570) is multi-threaded, use of fork() may lead to deadlocks in the child.
[2024-04-29T20:00:10.658+0000] {standard_task_runner.py:63} INFO - Started process 1587 to run task
[2024-04-29T20:00:10.719+0000] {task_command.py:426} INFO - Running <TaskInstance: predict_v11.train scheduled__2024-04-28T00:00:00+00:00 [running]> on host d4bc696c9a4e
[2024-04-29T20:00:10.797+0000] {taskinstance.py:2644} INFO - Exporting env vars: AIRFLOW_CTX_DAG_OWNER='mosula' AIRFLOW_CTX_DAG_ID='predict_v11' AIRFLOW_CTX_TASK_ID='train' AIRFLOW_CTX_EXECUTION_DATE='2024-04-28T00:00:00+00:00' AIRFLOW_CTX_TRY_NUMBER='1' AIRFLOW_CTX_DAG_RUN_ID='scheduled__2024-04-28T00:00:00+00:00'
[2024-04-29T20:00:10.798+0000] {taskinstance.py:430} INFO - ::endgroup::
[2024-04-29T20:00:10.846+0000] {logging_mixin.py:188} WARNING - /opt/***/dags/dag_predict.py:22 UserWarning: pandas only supports SQLAlchemy connectable (engine/connection) or database string URI or sqlite3 DBAPI2 connection. Other DBAPI2 objects are not tested. Please consider using SQLAlchemy.
[2024-04-29T20:00:11.140+0000] {taskinstance.py:441} INFO - ::group::Post task execution logs
[2024-04-29T20:00:11.143+0000] {taskinstance.py:2890} ERROR - Task failed with exception
Traceback (most recent call last):
  File "/home/airflow/.local/lib/python3.12/site-packages/airflow/models/taskinstance.py", line 465, in _execute_task
    result = _execute_callable(context=context, **execute_callable_kwargs)
             ^^^^^^^^^^^^^^^^^^^^^^^^^^^^^^^^^^^^^^^^^^^^^^^^^^^^^^^^^^^^^
  File "/home/airflow/.local/lib/python3.12/site-packages/airflow/models/taskinstance.py", line 432, in _execute_callable
    return execute_callable(context=context, **execute_callable_kwargs)
           ^^^^^^^^^^^^^^^^^^^^^^^^^^^^^^^^^^^^^^^^^^^^^^^^^^^^^^^^^^^^
  File "/home/airflow/.local/lib/python3.12/site-packages/airflow/models/baseoperator.py", line 400, in wrapper
    return func(self, *args, **kwargs)
           ^^^^^^^^^^^^^^^^^^^^^^^^^^^
  File "/home/airflow/.local/lib/python3.12/site-packages/airflow/operators/python.py", line 235, in execute
    return_value = self.execute_callable()
                   ^^^^^^^^^^^^^^^^^^^^^^^
  File "/home/airflow/.local/lib/python3.12/site-packages/airflow/operators/python.py", line 252, in execute_callable
    return self.python_callable(*self.op_args, **self.op_kwargs)
           ^^^^^^^^^^^^^^^^^^^^^^^^^^^^^^^^^^^^^^^^^^^^^^^^^^^^^
  File "/opt/airflow/dags/dag_predict.py", line 43, in predict
    cur.execute(sql)
psycopg2.errors.UndefinedColumn: column "predictions" of relation "churn_raw" does not exist
LINE 2: ...   INSERT INTO churn_raw (customer_id, hist_date, prediction...
                                                             ^

[2024-04-29T20:00:11.160+0000] {taskinstance.py:1205} INFO - Marking task as UP_FOR_RETRY. dag_id=predict_v11, task_id=train, execution_date=20240428T000000, start_date=20240429T200010, end_date=20240429T200011
[2024-04-29T20:00:11.176+0000] {standard_task_runner.py:110} ERROR - Failed to execute job 10 for task train (column "predictions" of relation "churn_raw" does not exist
LINE 2: ...   INSERT INTO churn_raw (customer_id, hist_date, prediction...
                                                             ^
; 1587)
[2024-04-29T20:00:11.206+0000] {local_task_job_runner.py:240} INFO - Task exited with return code 1
[2024-04-29T20:00:11.221+0000] {taskinstance.py:3482} INFO - 0 downstream tasks scheduled from follow-on schedule check
[2024-04-29T20:00:11.223+0000] {local_task_job_runner.py:222} INFO - ::endgroup::
