[2024-04-29T20:01:17.112+0000] {local_task_job_runner.py:120} INFO - ::group::Pre task execution logs
[2024-04-29T20:01:17.142+0000] {taskinstance.py:2073} INFO - Dependencies all met for dep_context=non-requeueable deps ti=<TaskInstance: predict_v12.train scheduled__2024-04-28T00:00:00+00:00 [queued]>
[2024-04-29T20:01:17.151+0000] {taskinstance.py:2073} INFO - Dependencies all met for dep_context=requeueable deps ti=<TaskInstance: predict_v12.train scheduled__2024-04-28T00:00:00+00:00 [queued]>
[2024-04-29T20:01:17.154+0000] {taskinstance.py:2303} INFO - Starting attempt 1 of 6
[2024-04-29T20:01:17.168+0000] {taskinstance.py:2327} INFO - Executing <Task(PythonOperator): train> on 2024-04-28 00:00:00+00:00
[2024-04-29T20:01:17.179+0000] {standard_task_runner.py:90} INFO - Running: ['***', 'tasks', 'run', 'predict_v12', 'train', 'scheduled__2024-04-28T00:00:00+00:00', '--job-id', '11', '--raw', '--subdir', 'DAGS_FOLDER/dag_predict.py', '--cfg-path', '/tmp/tmp45wctsx6']
[2024-04-29T20:01:17.182+0000] {standard_task_runner.py:91} INFO - Job 11: Subtask train
[2024-04-29T20:01:17.183+0000] {logging_mixin.py:188} WARNING - /home/***/.local/lib/python3.12/site-packages/***/task/task_runner/standard_task_runner.py:61 DeprecationWarning: This process (pid=1748) is multi-threaded, use of fork() may lead to deadlocks in the child.
[2024-04-29T20:01:17.184+0000] {standard_task_runner.py:63} INFO - Started process 1765 to run task
[2024-04-29T20:01:17.232+0000] {task_command.py:426} INFO - Running <TaskInstance: predict_v12.train scheduled__2024-04-28T00:00:00+00:00 [running]> on host d4bc696c9a4e
[2024-04-29T20:01:17.309+0000] {taskinstance.py:2644} INFO - Exporting env vars: AIRFLOW_CTX_DAG_OWNER='mosula' AIRFLOW_CTX_DAG_ID='predict_v12' AIRFLOW_CTX_TASK_ID='train' AIRFLOW_CTX_EXECUTION_DATE='2024-04-28T00:00:00+00:00' AIRFLOW_CTX_TRY_NUMBER='1' AIRFLOW_CTX_DAG_RUN_ID='scheduled__2024-04-28T00:00:00+00:00'
[2024-04-29T20:01:17.310+0000] {taskinstance.py:430} INFO - ::endgroup::
[2024-04-29T20:01:17.339+0000] {logging_mixin.py:188} WARNING - /opt/***/dags/dag_predict.py:22 UserWarning: pandas only supports SQLAlchemy connectable (engine/connection) or database string URI or sqlite3 DBAPI2 connection. Other DBAPI2 objects are not tested. Please consider using SQLAlchemy.
[2024-04-29T20:01:17.577+0000] {taskinstance.py:441} INFO - ::group::Post task execution logs
[2024-04-29T20:01:17.579+0000] {taskinstance.py:2890} ERROR - Task failed with exception
Traceback (most recent call last):
  File "/home/airflow/.local/lib/python3.12/site-packages/airflow/models/taskinstance.py", line 465, in _execute_task
    result = _execute_callable(context=context, **execute_callable_kwargs)
             ^^^^^^^^^^^^^^^^^^^^^^^^^^^^^^^^^^^^^^^^^^^^^^^^^^^^^^^^^^^^^
  File "/home/airflow/.local/lib/python3.12/site-packages/airflow/models/taskinstance.py", line 432, in _execute_callable
    return execute_callable(context=context, **execute_callable_kwargs)
           ^^^^^^^^^^^^^^^^^^^^^^^^^^^^^^^^^^^^^^^^^^^^^^^^^^^^^^^^^^^^
  File "/home/airflow/.local/lib/python3.12/site-packages/airflow/models/baseoperator.py", line 400, in wrapper
    return func(self, *args, **kwargs)
           ^^^^^^^^^^^^^^^^^^^^^^^^^^^
  File "/home/airflow/.local/lib/python3.12/site-packages/airflow/operators/python.py", line 235, in execute
    return_value = self.execute_callable()
                   ^^^^^^^^^^^^^^^^^^^^^^^
  File "/home/airflow/.local/lib/python3.12/site-packages/airflow/operators/python.py", line 252, in execute_callable
    return self.python_callable(*self.op_args, **self.op_kwargs)
           ^^^^^^^^^^^^^^^^^^^^^^^^^^^^^^^^^^^^^^^^^^^^^^^^^^^^^
  File "/opt/airflow/dags/dag_predict.py", line 34, in predict
    df = df.loc[:, ['customer_id', 'hist_date', 'predictions']]
         ~~~~~~^^^^^^^^^^^^^^^^^^^^^^^^^^^^^^^^^^^^^^^^^^^^^^^^
  File "/home/airflow/.local/lib/python3.12/site-packages/pandas/core/indexing.py", line 1184, in __getitem__
    return self._getitem_tuple(key)
           ^^^^^^^^^^^^^^^^^^^^^^^^
  File "/home/airflow/.local/lib/python3.12/site-packages/pandas/core/indexing.py", line 1377, in _getitem_tuple
    return self._getitem_tuple_same_dim(tup)
           ^^^^^^^^^^^^^^^^^^^^^^^^^^^^^^^^^
  File "/home/airflow/.local/lib/python3.12/site-packages/pandas/core/indexing.py", line 1020, in _getitem_tuple_same_dim
    retval = getattr(retval, self.name)._getitem_axis(key, axis=i)
             ^^^^^^^^^^^^^^^^^^^^^^^^^^^^^^^^^^^^^^^^^^^^^^^^^^^^^
  File "/home/airflow/.local/lib/python3.12/site-packages/pandas/core/indexing.py", line 1420, in _getitem_axis
    return self._getitem_iterable(key, axis=axis)
           ^^^^^^^^^^^^^^^^^^^^^^^^^^^^^^^^^^^^^^
  File "/home/airflow/.local/lib/python3.12/site-packages/pandas/core/indexing.py", line 1360, in _getitem_iterable
    keyarr, indexer = self._get_listlike_indexer(key, axis)
                      ^^^^^^^^^^^^^^^^^^^^^^^^^^^^^^^^^^^^^
  File "/home/airflow/.local/lib/python3.12/site-packages/pandas/core/indexing.py", line 1558, in _get_listlike_indexer
    keyarr, indexer = ax._get_indexer_strict(key, axis_name)
                      ^^^^^^^^^^^^^^^^^^^^^^^^^^^^^^^^^^^^^^
  File "/home/airflow/.local/lib/python3.12/site-packages/pandas/core/indexes/base.py", line 6200, in _get_indexer_strict
    self._raise_if_missing(keyarr, indexer, axis_name)
  File "/home/airflow/.local/lib/python3.12/site-packages/pandas/core/indexes/base.py", line 6252, in _raise_if_missing
    raise KeyError(f"{not_found} not in index")
KeyError: "['predictions'] not in index"
[2024-04-29T20:01:17.608+0000] {taskinstance.py:1205} INFO - Marking task as UP_FOR_RETRY. dag_id=predict_v12, task_id=train, execution_date=20240428T000000, start_date=20240429T200117, end_date=20240429T200117
[2024-04-29T20:01:17.620+0000] {standard_task_runner.py:110} ERROR - Failed to execute job 11 for task train ("['predictions'] not in index"; 1765)
[2024-04-29T20:01:17.644+0000] {local_task_job_runner.py:240} INFO - Task exited with return code 1
[2024-04-29T20:01:17.663+0000] {taskinstance.py:3482} INFO - 0 downstream tasks scheduled from follow-on schedule check
[2024-04-29T20:01:17.668+0000] {local_task_job_runner.py:222} INFO - ::endgroup::
