[2024-04-29T19:56:48.038+0000] {local_task_job_runner.py:120} INFO - ::group::Pre task execution logs
[2024-04-29T19:56:48.110+0000] {taskinstance.py:2073} INFO - Dependencies all met for dep_context=non-requeueable deps ti=<TaskInstance: predict_v8.train scheduled__2024-04-28T00:00:00+00:00 [queued]>
[2024-04-29T19:56:48.131+0000] {taskinstance.py:2073} INFO - Dependencies all met for dep_context=requeueable deps ti=<TaskInstance: predict_v8.train scheduled__2024-04-28T00:00:00+00:00 [queued]>
[2024-04-29T19:56:48.134+0000] {taskinstance.py:2303} INFO - Starting attempt 1 of 6
[2024-04-29T19:56:48.161+0000] {taskinstance.py:2327} INFO - Executing <Task(PythonOperator): train> on 2024-04-28 00:00:00+00:00
[2024-04-29T19:56:48.197+0000] {standard_task_runner.py:90} INFO - Running: ['***', 'tasks', 'run', 'predict_v8', 'train', 'scheduled__2024-04-28T00:00:00+00:00', '--job-id', '7', '--raw', '--subdir', 'DAGS_FOLDER/dag_predict.py', '--cfg-path', '/tmp/tmp8oi_9ghh']
[2024-04-29T19:56:48.207+0000] {standard_task_runner.py:91} INFO - Job 7: Subtask train
[2024-04-29T19:56:48.210+0000] {logging_mixin.py:188} WARNING - /home/***/.local/lib/python3.12/site-packages/***/task/task_runner/standard_task_runner.py:61 DeprecationWarning: This process (pid=995) is multi-threaded, use of fork() may lead to deadlocks in the child.
[2024-04-29T19:56:48.213+0000] {standard_task_runner.py:63} INFO - Started process 1045 to run task
[2024-04-29T19:56:48.511+0000] {task_command.py:426} INFO - Running <TaskInstance: predict_v8.train scheduled__2024-04-28T00:00:00+00:00 [running]> on host d4bc696c9a4e
[2024-04-29T19:56:49.347+0000] {taskinstance.py:2644} INFO - Exporting env vars: AIRFLOW_CTX_DAG_OWNER='mosula' AIRFLOW_CTX_DAG_ID='predict_v8' AIRFLOW_CTX_TASK_ID='train' AIRFLOW_CTX_EXECUTION_DATE='2024-04-28T00:00:00+00:00' AIRFLOW_CTX_TRY_NUMBER='1' AIRFLOW_CTX_DAG_RUN_ID='scheduled__2024-04-28T00:00:00+00:00'
[2024-04-29T19:56:49.355+0000] {taskinstance.py:430} INFO - ::endgroup::
[2024-04-29T19:56:50.304+0000] {logging_mixin.py:188} WARNING - /opt/***/dags/dag_predict.py:22 UserWarning: pandas only supports SQLAlchemy connectable (engine/connection) or database string URI or sqlite3 DBAPI2 connection. Other DBAPI2 objects are not tested. Please consider using SQLAlchemy.
[2024-04-29T19:56:51.178+0000] {taskinstance.py:441} INFO - ::group::Post task execution logs
[2024-04-29T19:56:51.180+0000] {taskinstance.py:2890} ERROR - Task failed with exception
Traceback (most recent call last):
  File "/home/airflow/.local/lib/python3.12/site-packages/airflow/models/taskinstance.py", line 465, in _execute_task
    result = _execute_callable(context=context, **execute_callable_kwargs)
             ^^^^^^^^^^^^^^^^^^^^^^^^^^^^^^^^^^^^^^^^^^^^^^^^^^^^^^^^^^^^^
  File "/home/airflow/.local/lib/python3.12/site-packages/airflow/models/taskinstance.py", line 432, in _execute_callable
    return execute_callable(context=context, **execute_callable_kwargs)
           ^^^^^^^^^^^^^^^^^^^^^^^^^^^^^^^^^^^^^^^^^^^^^^^^^^^^^^^^^^^^
  File "/home/airflow/.local/lib/python3.12/site-packages/airflow/models/baseoperator.py", line 400, in wrapper
    return func(self, *args, **kwargs)
           ^^^^^^^^^^^^^^^^^^^^^^^^^^^
  File "/home/airflow/.local/lib/python3.12/site-packages/airflow/operators/python.py", line 235, in execute
    return_value = self.execute_callable()
                   ^^^^^^^^^^^^^^^^^^^^^^^
  File "/home/airflow/.local/lib/python3.12/site-packages/airflow/operators/python.py", line 252, in execute_callable
    return self.python_callable(*self.op_args, **self.op_kwargs)
           ^^^^^^^^^^^^^^^^^^^^^^^^^^^^^^^^^^^^^^^^^^^^^^^^^^^^^
  File "/opt/airflow/dags/dag_predict.py", line 33, in predict
    df['predictions'] = model.predict(df.drop(columns=['id', 'customer_id', 'hist_date']))
                        ^^^^^^^^^^^^^^^^^^^^^^^^^^^^^^^^^^^^^^^^^^^^^^^^^^^^^^^^^^^^^^^^^^
  File "/home/airflow/.local/lib/python3.12/site-packages/lightgbm/basic.py", line 4453, in predict
    return predictor.predict(
           ^^^^^^^^^^^^^^^^^^
  File "/home/airflow/.local/lib/python3.12/site-packages/lightgbm/basic.py", line 1159, in predict
    preds, nrow = self.__pred_for_np2d(
                  ^^^^^^^^^^^^^^^^^^^^^
  File "/home/airflow/.local/lib/python3.12/site-packages/lightgbm/basic.py", line 1306, in __pred_for_np2d
    return self.__inner_predict_np2d(
           ^^^^^^^^^^^^^^^^^^^^^^^^^^
  File "/home/airflow/.local/lib/python3.12/site-packages/lightgbm/basic.py", line 1259, in __inner_predict_np2d
    _safe_call(_LIB.LGBM_BoosterPredictForMat(
  File "/home/airflow/.local/lib/python3.12/site-packages/lightgbm/basic.py", line 263, in _safe_call
    raise LightGBMError(_LIB.LGBM_GetLastError().decode('utf-8'))
lightgbm.basic.LightGBMError: The number of features in data (31) is not the same as it was in training data (30).
You can set ``predict_disable_shape_check=true`` to discard this error, but please be aware what you are doing.
[2024-04-29T19:56:51.235+0000] {taskinstance.py:1205} INFO - Marking task as UP_FOR_RETRY. dag_id=predict_v8, task_id=train, execution_date=20240428T000000, start_date=20240429T195648, end_date=20240429T195651
[2024-04-29T19:56:51.272+0000] {standard_task_runner.py:110} ERROR - Failed to execute job 7 for task train (The number of features in data (31) is not the same as it was in training data (30).
You can set ``predict_disable_shape_check=true`` to discard this error, but please be aware what you are doing.; 1045)
[2024-04-29T19:56:51.302+0000] {local_task_job_runner.py:240} INFO - Task exited with return code 1
[2024-04-29T19:56:51.329+0000] {taskinstance.py:3482} INFO - 0 downstream tasks scheduled from follow-on schedule check
[2024-04-29T19:56:51.333+0000] {local_task_job_runner.py:222} INFO - ::endgroup::
