[2024-04-29T16:26:43.338+0000] {task_context_logger.py:104} ERROR - Executor reports task instance <TaskInstance: fill_data_v3.raw scheduled__2024-04-28T00:00:00+00:00 [queued]> finished (failed) although the task says it's queued. (Info: None) Was the task killed externally?
