[2024-04-29T16:21:41.468+0000] {local_task_job_runner.py:120} INFO - ::group::Pre task execution logs
[2024-04-29T16:21:41.649+0000] {taskinstance.py:2073} INFO - Dependencies all met for dep_context=non-requeueable deps ti=<TaskInstance: fill_data_v3.raw scheduled__2024-04-28T00:00:00+00:00 [queued]>
[2024-04-29T16:21:41.662+0000] {taskinstance.py:2073} INFO - Dependencies all met for dep_context=requeueable deps ti=<TaskInstance: fill_data_v3.raw scheduled__2024-04-28T00:00:00+00:00 [queued]>
[2024-04-29T16:21:41.664+0000] {taskinstance.py:2303} INFO - Starting attempt 1 of 6
[2024-04-29T16:21:41.678+0000] {taskinstance.py:2327} INFO - Executing <Task(PythonOperator): raw> on 2024-04-28 00:00:00+00:00
[2024-04-29T16:21:41.686+0000] {standard_task_runner.py:90} INFO - Running: ['***', 'tasks', 'run', 'fill_data_v3', 'raw', 'scheduled__2024-04-28T00:00:00+00:00', '--job-id', '5', '--raw', '--subdir', 'DAGS_FOLDER/dag_raw_processed.py', '--cfg-path', '/tmp/tmpkv5av7r6']
[2024-04-29T16:21:41.688+0000] {standard_task_runner.py:91} INFO - Job 5: Subtask raw
[2024-04-29T16:21:41.688+0000] {logging_mixin.py:188} WARNING - /home/***/.local/lib/python3.12/site-packages/***/task/task_runner/standard_task_runner.py:61 DeprecationWarning: This process (pid=393) is multi-threaded, use of fork() may lead to deadlocks in the child.
[2024-04-29T16:21:41.689+0000] {standard_task_runner.py:63} INFO - Started process 395 to run task
[2024-04-29T16:21:41.728+0000] {task_command.py:426} INFO - Running <TaskInstance: fill_data_v3.raw scheduled__2024-04-28T00:00:00+00:00 [running]> on host 8865bf60ce19
[2024-04-29T16:21:41.811+0000] {taskinstance.py:2644} INFO - Exporting env vars: AIRFLOW_CTX_DAG_OWNER='mosula' AIRFLOW_CTX_DAG_ID='fill_data_v3' AIRFLOW_CTX_TASK_ID='raw' AIRFLOW_CTX_EXECUTION_DATE='2024-04-28T00:00:00+00:00' AIRFLOW_CTX_TRY_NUMBER='1' AIRFLOW_CTX_DAG_RUN_ID='scheduled__2024-04-28T00:00:00+00:00'
[2024-04-29T16:21:41.813+0000] {taskinstance.py:430} INFO - ::endgroup::
[2024-04-29T16:21:41.828+0000] {logging_mixin.py:188} INFO - ['dags', 'logs', '***.cfg', 'data']
[2024-04-29T16:21:41.831+0000] {taskinstance.py:441} INFO - ::group::Post task execution logs
[2024-04-29T16:21:41.832+0000] {taskinstance.py:2890} ERROR - Task failed with exception
Traceback (most recent call last):
  File "/home/airflow/.local/lib/python3.12/site-packages/airflow/models/taskinstance.py", line 465, in _execute_task
    result = _execute_callable(context=context, **execute_callable_kwargs)
             ^^^^^^^^^^^^^^^^^^^^^^^^^^^^^^^^^^^^^^^^^^^^^^^^^^^^^^^^^^^^^
  File "/home/airflow/.local/lib/python3.12/site-packages/airflow/models/taskinstance.py", line 432, in _execute_callable
    return execute_callable(context=context, **execute_callable_kwargs)
           ^^^^^^^^^^^^^^^^^^^^^^^^^^^^^^^^^^^^^^^^^^^^^^^^^^^^^^^^^^^^
  File "/home/airflow/.local/lib/python3.12/site-packages/airflow/models/baseoperator.py", line 400, in wrapper
    return func(self, *args, **kwargs)
           ^^^^^^^^^^^^^^^^^^^^^^^^^^^
  File "/home/airflow/.local/lib/python3.12/site-packages/airflow/operators/python.py", line 235, in execute
    return_value = self.execute_callable()
                   ^^^^^^^^^^^^^^^^^^^^^^^
  File "/home/airflow/.local/lib/python3.12/site-packages/airflow/operators/python.py", line 252, in execute_callable
    return self.python_callable(*self.op_args, **self.op_kwargs)
           ^^^^^^^^^^^^^^^^^^^^^^^^^^^^^^^^^^^^^^^^^^^^^^^^^^^^^
  File "/opt/airflow/dags/dag_raw_processed.py", line 19, in fill_raw
    df = pd.read_csv(os.path.join(os.getcwd(), 'data', data_name))
         ^^^^^^^^^^^^^^^^^^^^^^^^^^^^^^^^^^^^^^^^^^^^^^^^^^^^^^^^^
  File "/home/airflow/.local/lib/python3.12/site-packages/pandas/io/parsers/readers.py", line 1026, in read_csv
    return _read(filepath_or_buffer, kwds)
           ^^^^^^^^^^^^^^^^^^^^^^^^^^^^^^^
  File "/home/airflow/.local/lib/python3.12/site-packages/pandas/io/parsers/readers.py", line 620, in _read
    parser = TextFileReader(filepath_or_buffer, **kwds)
             ^^^^^^^^^^^^^^^^^^^^^^^^^^^^^^^^^^^^^^^^^^
  File "/home/airflow/.local/lib/python3.12/site-packages/pandas/io/parsers/readers.py", line 1620, in __init__
    self._engine = self._make_engine(f, self.engine)
                   ^^^^^^^^^^^^^^^^^^^^^^^^^^^^^^^^^
  File "/home/airflow/.local/lib/python3.12/site-packages/pandas/io/parsers/readers.py", line 1880, in _make_engine
    self.handles = get_handle(
                   ^^^^^^^^^^^
  File "/home/airflow/.local/lib/python3.12/site-packages/pandas/io/common.py", line 873, in get_handle
    handle = open(
             ^^^^^
FileNotFoundError: [Errno 2] No such file or directory: '/opt/airflow/data/data.csv'
[2024-04-29T16:21:41.849+0000] {taskinstance.py:1205} INFO - Marking task as UP_FOR_RETRY. dag_id=fill_data_v3, task_id=raw, execution_date=20240428T000000, start_date=20240429T162141, end_date=20240429T162141
[2024-04-29T16:21:41.863+0000] {standard_task_runner.py:110} ERROR - Failed to execute job 5 for task raw ([Errno 2] No such file or directory: '/opt/airflow/data/data.csv'; 395)
[2024-04-29T16:21:41.904+0000] {local_task_job_runner.py:240} INFO - Task exited with return code 1
[2024-04-29T16:21:41.928+0000] {taskinstance.py:3482} INFO - 0 downstream tasks scheduled from follow-on schedule check
[2024-04-29T16:21:41.933+0000] {local_task_job_runner.py:222} INFO - ::endgroup::
